2023-11-24 10:16:37,493 INFO    MainThread:7127 [internal.py:wandb_internal():62] W&B internal server running at pid: 7127
2023-11-24 10:16:37,497 DEBUG   HandlerThread:7127 [handler.py:handle_request():54] handle_request: check_version
2023-11-24 10:16:37,498 INFO    WriterThread:7127 [datastore.py:open_for_write():76] open: /content/drive/MyDrive/on-policy/onpolicy/scripts/results/StarCraft2/2m_vs_1z/rmappo/check/wandb/run-20231124_101636-2mqra48l/run-2mqra48l.wandb
2023-11-24 10:16:37,500 DEBUG   SenderThread:7127 [sender.py:send():88] send: header
2023-11-24 10:16:37,501 DEBUG   SenderThread:7127 [sender.py:send():88] send: request
2023-11-24 10:16:37,502 DEBUG   SenderThread:7127 [sender.py:send_request():97] send_request: check_version
2023-11-24 10:16:37,505 DEBUG   Thread-4  :7127 [connectionpool.py:_new_conn():823] Starting new HTTPS connection (1): pypi.org:443
2023-11-24 10:16:37,535 DEBUG   Thread-4  :7127 [connectionpool.py:_make_request():393] https://pypi.org:443 "GET /pypi/wandb/json HTTP/1.1" 200 80491
2023-11-24 10:16:37,552 DEBUG   SenderThread:7127 [sender.py:send():88] send: run
2023-11-24 10:16:37,589 DEBUG   SenderThread:7127 [cmd.py:execute():719] Popen(['git', 'cat-file', '--batch-check'], cwd=/content/drive/MyDrive/on-policy, universal_newlines=False, shell=None, istream=<valid stream>)
2023-11-24 10:16:37,615 DEBUG   SenderThread:7127 [connectionpool.py:_new_conn():823] Starting new HTTPS connection (1): api.wandb.ai:443
2023-11-24 10:16:37,753 DEBUG   SenderThread:7127 [connectionpool.py:_make_request():393] https://api.wandb.ai:443 "POST /graphql HTTP/1.1" 403 None
2023-11-24 10:16:37,756 ERROR   SenderThread:7127 [internal_api.py:execute():131] 403 response executing GraphQL.
2023-11-24 10:16:37,756 ERROR   SenderThread:7127 [internal_api.py:execute():132] {"errors":[{"message":"permission denied","path":["upsertBucket"],"extensions":{"code":"PERMISSION_ERROR"}}],"data":{"upsertBucket":null}}
2023-11-24 10:16:38,553 INFO    WriterThread:7127 [datastore.py:close():257] close: /content/drive/MyDrive/on-policy/onpolicy/scripts/results/StarCraft2/2m_vs_1z/rmappo/check/wandb/run-20231124_101636-2mqra48l/run-2mqra48l.wandb
2023-11-24 10:16:38,553 INFO    HandlerThread:7127 [handler.py:finish():267] shutting down handler
2023-11-24 10:16:38,555 ERROR   MainThread:7127 [internal.py:wandb_internal():128] Thread SenderThread:
Traceback (most recent call last):
  File "/usr/local/envs/marl/lib/python3.6/site-packages/wandb/old/retry.py", line 96, in __call__
    result = self._call_fn(*args, **kwargs)
  File "/usr/local/envs/marl/lib/python3.6/site-packages/wandb/internal/internal_api.py", line 134, in execute
    six.reraise(*sys.exc_info())
  File "/usr/local/envs/marl/lib/python3.6/site-packages/six.py", line 703, in reraise
    raise value
  File "/usr/local/envs/marl/lib/python3.6/site-packages/wandb/internal/internal_api.py", line 128, in execute
    return self.client.execute(*args, **kwargs)
  File "/usr/local/envs/marl/lib/python3.6/site-packages/wandb/vendor/gql-0.2.0/gql/client.py", line 52, in execute
    result = self._get_result(document, *args, **kwargs)
  File "/usr/local/envs/marl/lib/python3.6/site-packages/wandb/vendor/gql-0.2.0/gql/client.py", line 60, in _get_result
    return self.transport.execute(document, *args, **kwargs)
  File "/usr/local/envs/marl/lib/python3.6/site-packages/wandb/vendor/gql-0.2.0/gql/transport/requests.py", line 39, in execute
    request.raise_for_status()
  File "/usr/local/envs/marl/lib/python3.6/site-packages/requests/models.py", line 941, in raise_for_status
    raise HTTPError(http_error_msg, response=self)
requests.exceptions.HTTPError: 403 Client Error: Forbidden for url: https://api.wandb.ai/graphql

During handling of the above exception, another exception occurred:

Traceback (most recent call last):
  File "/usr/local/envs/marl/lib/python3.6/site-packages/wandb/apis/normalize.py", line 24, in wrapper
    return func(*args, **kwargs)
  File "/usr/local/envs/marl/lib/python3.6/site-packages/wandb/internal/internal_api.py", line 968, in upsert_run
    response = self.gql(mutation, variable_values=variable_values, **kwargs)
  File "/usr/local/envs/marl/lib/python3.6/site-packages/wandb/old/retry.py", line 105, in __call__
    if not check_retry_fn(e):
  File "/usr/local/envs/marl/lib/python3.6/site-packages/wandb/util.py", line 585, in no_retry_auth
    raise CommError("Permission denied, ask the project owner to grant you access")
wandb.errors.error.CommError: Permission denied, ask the project owner to grant you access

During handling of the above exception, another exception occurred:

Traceback (most recent call last):
  File "/usr/local/envs/marl/lib/python3.6/site-packages/wandb/internal/internal_util.py", line 33, in run
    self._run()
  File "/usr/local/envs/marl/lib/python3.6/site-packages/wandb/internal/internal_util.py", line 60, in _run
    self._process(record)
  File "/usr/local/envs/marl/lib/python3.6/site-packages/wandb/internal/internal.py", line 232, in _process
    self._sm.send(record)
  File "/usr/local/envs/marl/lib/python3.6/site-packages/wandb/internal/sender.py", line 90, in send
    send_handler(record)
  File "/usr/local/envs/marl/lib/python3.6/site-packages/wandb/internal/sender.py", line 360, in send_run
    self._init_run(run, config_dict)
  File "/usr/local/envs/marl/lib/python3.6/site-packages/wandb/internal/sender.py", line 396, in _init_run
    commit=repo.last_commit,
  File "/usr/local/envs/marl/lib/python3.6/site-packages/wandb/apis/normalize.py", line 62, in wrapper
    six.reraise(CommError, CommError(message, err), sys.exc_info()[2])
  File "/usr/local/envs/marl/lib/python3.6/site-packages/six.py", line 702, in reraise
    raise value.with_traceback(tb)
  File "/usr/local/envs/marl/lib/python3.6/site-packages/wandb/apis/normalize.py", line 24, in wrapper
    return func(*args, **kwargs)
  File "/usr/local/envs/marl/lib/python3.6/site-packages/wandb/internal/internal_api.py", line 968, in upsert_run
    response = self.gql(mutation, variable_values=variable_values, **kwargs)
  File "/usr/local/envs/marl/lib/python3.6/site-packages/wandb/old/retry.py", line 105, in __call__
    if not check_retry_fn(e):
  File "/usr/local/envs/marl/lib/python3.6/site-packages/wandb/util.py", line 585, in no_retry_auth
    raise CommError("Permission denied, ask the project owner to grant you access")
wandb.errors.error.CommError: Permission denied, ask the project owner to grant you access
2023-11-24 10:16:38,585 INFO    Dummy-5   :7127 [internal.py:handle_exit():137] Internal process exited
