{'all_args': {'algorithm_name': 'rmappo', 'experiment_name': 'check', 'seed': 1, 'cuda': True, 'cuda_deterministic': True, 'n_training_threads': 1, 'n_rollout_threads': 8, 'n_eval_rollout_threads': 1, 'n_render_rollout_threads': 1, 'num_env_steps': 10000000, 'user_name': 'marl', 'use_wandb': True, 'env_name': 'StarCraft2', 'use_obs_instead_of_state': False, 'episode_length': 400, 'share_policy': True, 'use_centralized_V': True, 'stacked_frames': 1, 'use_stacked_frames': False, 'hidden_size': 64, 'layer_N': 1, 'use_ReLU': True, 'use_popart': False, 'use_valuenorm': True, 'use_feature_normalization': True, 'use_orthogonal': True, 'gain': 0.01, 'use_naive_recurrent_policy': False, 'use_recurrent_policy': True, 'recurrent_N': 1, 'data_chunk_length': 10, 'lr': 0.0005, 'critic_lr': 0.0005, 'opti_eps': 1e-05, 'weight_decay': 0, 'kl_threshold': 0.01, 'ls_step': 10, 'accept_ratio': 0.5, 'ppo_epoch': 15, 'use_clipped_value_loss': True, 'clip_param': 0.2, 'num_mini_batch': 1, 'entropy_coef': 0.01, 'value_loss_coef': 1, 'use_max_grad_norm': True, 'max_grad_norm': 10.0, 'use_gae': True, 'gamma': 0.99, 'gae_lambda': 0.95, 'use_proper_time_limits': False, 'use_huber_loss': True, 'use_value_active_masks': False, 'use_policy_active_masks': True, 'huber_delta': 10.0, 'use_linear_lr_decay': False, 'save_interval': 1, 'log_interval': 5, 'use_eval': True, 'eval_interval': 25, 'eval_episodes': 32, 'save_gifs': False, 'use_render': False, 'render_episodes': 5, 'ifi': 0.1, 'model_dir': None, 'encode_state': False, 'n_block': 1, 'n_embd': 64, 'n_head': 1, 'dec_actor': False, 'share_actor': False, 'train_maps': None, 'eval_maps': None, 'map_name': '2m_vs_1z', 'units': '10v10', 'add_move_state': False, 'add_local_obs': False, 'add_distance_state': False, 'add_enemy_action_state': False, 'add_agent_id': False, 'add_visible_state': False, 'add_xy_state': False, 'use_state_agent': True, 'use_mustalive': True, 'add_center_xy': True}, 'envs': <onpolicy.envs.env_wrappers.ShareSubprocVecEnv object at 0x7abf73b24860>, 'eval_envs': <onpolicy.envs.env_wrappers.ShareDummyVecEnv object at 0x7abf73a453c8>, 'num_agents': 2, 'device': device(type='cpu'), 'run_dir': PosixPath('/content/drive/MyDrive/on-policy/onpolicy/scripts/results/StarCraft2/2m_vs_1z/rmappo/check')}
obs_space:  [[36, [1, 12], [1, 6], [1, 4], [1, 14]], [36, [1, 12], [1, 6], [1, 4], [1, 14]]]
share_obs_space:  [[44, [1, 15], [1, 9], [1, 4], [1, 16]], [44, [1, 15], [1, 9], [1, 4], [1, 16]]]
act_space:  [Discrete(7), Discrete(7)]
ERROR:absl:Failed to launch
Traceback (most recent call last):
  File "/usr/local/envs/marl/lib/python3.6/site-packages/pysc2/lib/sc_process.py", line 201, in _launch
    return subprocess.Popen(args, cwd=run_config.cwd, env=run_config.env)
  File "/usr/local/envs/marl/lib/python3.6/subprocess.py", line 707, in __init__
    restore_signals, start_new_session)
  File "/usr/local/envs/marl/lib/python3.6/subprocess.py", line 1326, in _execute_child
    raise child_exception_type(errno_num, err_msg)
PermissionError: [Errno 13] Permission denied
Process Process-3:
ERROR:absl:Failed to launch
Traceback (most recent call last):
  File "/usr/local/envs/marl/lib/python3.6/site-packages/pysc2/lib/sc_process.py", line 201, in _launch
    return subprocess.Popen(args, cwd=run_config.cwd, env=run_config.env)
  File "/usr/local/envs/marl/lib/python3.6/subprocess.py", line 707, in __init__
    restore_signals, start_new_session)
  File "/usr/local/envs/marl/lib/python3.6/subprocess.py", line 1326, in _execute_child
    raise child_exception_type(errno_num, err_msg)
PermissionError: [Errno 13] Permission denied
Process Process-7:
ERROR:absl:Failed to launch
Traceback (most recent call last):
  File "/usr/local/envs/marl/lib/python3.6/site-packages/pysc2/lib/sc_process.py", line 201, in _launch
    return subprocess.Popen(args, cwd=run_config.cwd, env=run_config.env)
  File "/usr/local/envs/marl/lib/python3.6/subprocess.py", line 707, in __init__
    restore_signals, start_new_session)
  File "/usr/local/envs/marl/lib/python3.6/subprocess.py", line 1326, in _execute_child
    raise child_exception_type(errno_num, err_msg)
PermissionError: [Errno 13] Permission denied
Process Process-2:
ERROR:absl:Failed to launch
Traceback (most recent call last):
  File "/usr/local/envs/marl/lib/python3.6/site-packages/pysc2/lib/sc_process.py", line 201, in _launch
    return subprocess.Popen(args, cwd=run_config.cwd, env=run_config.env)
  File "/usr/local/envs/marl/lib/python3.6/subprocess.py", line 707, in __init__
    restore_signals, start_new_session)
  File "/usr/local/envs/marl/lib/python3.6/subprocess.py", line 1326, in _execute_child
    raise child_exception_type(errno_num, err_msg)
PermissionError: [Errno 13] Permission denied
Process Process-4:
ERROR:absl:Failed to launch
Traceback (most recent call last):
  File "/usr/local/envs/marl/lib/python3.6/site-packages/pysc2/lib/sc_process.py", line 201, in _launch
    return subprocess.Popen(args, cwd=run_config.cwd, env=run_config.env)
  File "/usr/local/envs/marl/lib/python3.6/subprocess.py", line 707, in __init__
    restore_signals, start_new_session)
  File "/usr/local/envs/marl/lib/python3.6/subprocess.py", line 1326, in _execute_child
    raise child_exception_type(errno_num, err_msg)
PermissionError: [Errno 13] Permission denied
Process Process-8:
ERROR:absl:Failed to launch
Traceback (most recent call last):
  File "/usr/local/envs/marl/lib/python3.6/site-packages/pysc2/lib/sc_process.py", line 201, in _launch
    return subprocess.Popen(args, cwd=run_config.cwd, env=run_config.env)
  File "/usr/local/envs/marl/lib/python3.6/subprocess.py", line 707, in __init__
    restore_signals, start_new_session)
  File "/usr/local/envs/marl/lib/python3.6/subprocess.py", line 1326, in _execute_child
    raise child_exception_type(errno_num, err_msg)
PermissionError: [Errno 13] Permission denied
Process Process-9:
ERROR:absl:Failed to launch
Traceback (most recent call last):
  File "/usr/local/envs/marl/lib/python3.6/site-packages/pysc2/lib/sc_process.py", line 201, in _launch
    return subprocess.Popen(args, cwd=run_config.cwd, env=run_config.env)
  File "/usr/local/envs/marl/lib/python3.6/subprocess.py", line 707, in __init__
    restore_signals, start_new_session)
  File "/usr/local/envs/marl/lib/python3.6/subprocess.py", line 1326, in _execute_child
    raise child_exception_type(errno_num, err_msg)
PermissionError: [Errno 13] Permission denied
Process Process-5:
ERROR:absl:Failed to launch
Traceback (most recent call last):
  File "/usr/local/envs/marl/lib/python3.6/site-packages/pysc2/lib/sc_process.py", line 201, in _launch
    return subprocess.Popen(args, cwd=run_config.cwd, env=run_config.env)
  File "/usr/local/envs/marl/lib/python3.6/subprocess.py", line 707, in __init__
    restore_signals, start_new_session)
  File "/usr/local/envs/marl/lib/python3.6/subprocess.py", line 1326, in _execute_child
    raise child_exception_type(errno_num, err_msg)
PermissionError: [Errno 13] Permission denied
Process Process-6:
Traceback (most recent call last):
  File "/usr/local/envs/marl/lib/python3.6/site-packages/pysc2/lib/sc_process.py", line 201, in _launch
    return subprocess.Popen(args, cwd=run_config.cwd, env=run_config.env)
  File "/usr/local/envs/marl/lib/python3.6/subprocess.py", line 707, in __init__
    restore_signals, start_new_session)
  File "/usr/local/envs/marl/lib/python3.6/subprocess.py", line 1326, in _execute_child
    raise child_exception_type(errno_num, err_msg)
PermissionError: [Errno 13] Permission denied

During handling of the above exception, another exception occurred:

Traceback (most recent call last):
  File "/usr/local/envs/marl/lib/python3.6/multiprocessing/process.py", line 249, in _bootstrap
    self.run()
  File "/usr/local/envs/marl/lib/python3.6/multiprocessing/process.py", line 93, in run
    self._target(*self._args, **self._kwargs)
  File "/content/drive/MyDrive/on-policy/onpolicy/envs/env_wrappers.py", line 316, in shareworker
    ob, s_ob, available_actions = env.reset()
  File "/content/drive/MyDrive/on-policy/onpolicy/envs/starcraft2/StarCraft2_Env.py", line 388, in reset
    self._launch()
  File "/content/drive/MyDrive/on-policy/onpolicy/envs/starcraft2/StarCraft2_Env.py", line 338, in _launch
    self._sc2_proc = self._run_config.start(window_size=self.window_size, want_rgb=False)
  File "/usr/local/envs/marl/lib/python3.6/site-packages/pysc2/run_configs/platforms.py", line 205, in start
    want_rgb=want_rgb, extra_args=extra_args, **kwargs)
  File "/usr/local/envs/marl/lib/python3.6/site-packages/pysc2/run_configs/platforms.py", line 88, in start
    self, exec_path=exec_path, version=self.version, **kwargs)
  File "/usr/local/envs/marl/lib/python3.6/site-packages/pysc2/lib/sc_process.py", line 140, in __init__
    self._proc = self._launch(run_config, args, **kwargs)
  File "/usr/local/envs/marl/lib/python3.6/site-packages/pysc2/lib/sc_process.py", line 204, in _launch
    raise SC2LaunchError("Failed to launch: %s" % args)
pysc2.lib.sc_process.SC2LaunchError: Failed to launch: ['/content/drive/MyDrive/on-policy/StarCraftII/Versions/Base75689/SC2_x64', '-listen', '127.0.0.1', '-port', '18562', '-dataDir', '/content/drive/MyDrive/on-policy/StarCraftII/', '-tempDir', '/tmp/sc-2oookgyn/']
Traceback (most recent call last):
  File "/usr/local/envs/marl/lib/python3.6/site-packages/pysc2/lib/sc_process.py", line 201, in _launch
    return subprocess.Popen(args, cwd=run_config.cwd, env=run_config.env)
  File "/usr/local/envs/marl/lib/python3.6/subprocess.py", line 707, in __init__
    restore_signals, start_new_session)
  File "/usr/local/envs/marl/lib/python3.6/subprocess.py", line 1326, in _execute_child
    raise child_exception_type(errno_num, err_msg)
PermissionError: [Errno 13] Permission denied

During handling of the above exception, another exception occurred:

Traceback (most recent call last):
  File "/usr/local/envs/marl/lib/python3.6/multiprocessing/process.py", line 249, in _bootstrap
    self.run()
  File "/usr/local/envs/marl/lib/python3.6/multiprocessing/process.py", line 93, in run
    self._target(*self._args, **self._kwargs)
  File "/content/drive/MyDrive/on-policy/onpolicy/envs/env_wrappers.py", line 316, in shareworker
    ob, s_ob, available_actions = env.reset()
  File "/content/drive/MyDrive/on-policy/onpolicy/envs/starcraft2/StarCraft2_Env.py", line 388, in reset
    self._launch()
  File "/content/drive/MyDrive/on-policy/onpolicy/envs/starcraft2/StarCraft2_Env.py", line 338, in _launch
    self._sc2_proc = self._run_config.start(window_size=self.window_size, want_rgb=False)
  File "/usr/local/envs/marl/lib/python3.6/site-packages/pysc2/run_configs/platforms.py", line 205, in start
    want_rgb=want_rgb, extra_args=extra_args, **kwargs)
  File "/usr/local/envs/marl/lib/python3.6/site-packages/pysc2/run_configs/platforms.py", line 88, in start
    self, exec_path=exec_path, version=self.version, **kwargs)
  File "/usr/local/envs/marl/lib/python3.6/site-packages/pysc2/lib/sc_process.py", line 140, in __init__
    self._proc = self._launch(run_config, args, **kwargs)
  File "/usr/local/envs/marl/lib/python3.6/site-packages/pysc2/lib/sc_process.py", line 204, in _launch
    raise SC2LaunchError("Failed to launch: %s" % args)
pysc2.lib.sc_process.SC2LaunchError: Failed to launch: ['/content/drive/MyDrive/on-policy/StarCraftII/Versions/Base75689/SC2_x64', '-listen', '127.0.0.1', '-port', '18076', '-dataDir', '/content/drive/MyDrive/on-policy/StarCraftII/', '-tempDir', '/tmp/sc-xhdye4z7/']
Traceback (most recent call last):
  File "/usr/local/envs/marl/lib/python3.6/site-packages/pysc2/lib/sc_process.py", line 201, in _launch
    return subprocess.Popen(args, cwd=run_config.cwd, env=run_config.env)
  File "/usr/local/envs/marl/lib/python3.6/subprocess.py", line 707, in __init__
    restore_signals, start_new_session)
  File "/usr/local/envs/marl/lib/python3.6/subprocess.py", line 1326, in _execute_child
    raise child_exception_type(errno_num, err_msg)
PermissionError: [Errno 13] Permission denied

During handling of the above exception, another exception occurred:

Traceback (most recent call last):
  File "/usr/local/envs/marl/lib/python3.6/multiprocessing/process.py", line 249, in _bootstrap
    self.run()
  File "/usr/local/envs/marl/lib/python3.6/multiprocessing/process.py", line 93, in run
    self._target(*self._args, **self._kwargs)
  File "/content/drive/MyDrive/on-policy/onpolicy/envs/env_wrappers.py", line 316, in shareworker
    ob, s_ob, available_actions = env.reset()
  File "/content/drive/MyDrive/on-policy/onpolicy/envs/starcraft2/StarCraft2_Env.py", line 388, in reset
    self._launch()
  File "/content/drive/MyDrive/on-policy/onpolicy/envs/starcraft2/StarCraft2_Env.py", line 338, in _launch
    self._sc2_proc = self._run_config.start(window_size=self.window_size, want_rgb=False)
  File "/usr/local/envs/marl/lib/python3.6/site-packages/pysc2/run_configs/platforms.py", line 205, in start
    want_rgb=want_rgb, extra_args=extra_args, **kwargs)
  File "/usr/local/envs/marl/lib/python3.6/site-packages/pysc2/run_configs/platforms.py", line 88, in start
    self, exec_path=exec_path, version=self.version, **kwargs)
  File "/usr/local/envs/marl/lib/python3.6/site-packages/pysc2/lib/sc_process.py", line 140, in __init__
    self._proc = self._launch(run_config, args, **kwargs)
  File "/usr/local/envs/marl/lib/python3.6/site-packages/pysc2/lib/sc_process.py", line 204, in _launch
    raise SC2LaunchError("Failed to launch: %s" % args)
pysc2.lib.sc_process.SC2LaunchError: Failed to launch: ['/content/drive/MyDrive/on-policy/StarCraftII/Versions/Base75689/SC2_x64', '-listen', '127.0.0.1', '-port', '21457', '-dataDir', '/content/drive/MyDrive/on-policy/StarCraftII/', '-tempDir', '/tmp/sc-2q1nsa63/']
Traceback (most recent call last):
  File "/usr/local/envs/marl/lib/python3.6/site-packages/pysc2/lib/sc_process.py", line 201, in _launch
    return subprocess.Popen(args, cwd=run_config.cwd, env=run_config.env)
  File "/usr/local/envs/marl/lib/python3.6/subprocess.py", line 707, in __init__
    restore_signals, start_new_session)
  File "/usr/local/envs/marl/lib/python3.6/subprocess.py", line 1326, in _execute_child
    raise child_exception_type(errno_num, err_msg)
PermissionError: [Errno 13] Permission denied

During handling of the above exception, another exception occurred:

Traceback (most recent call last):
  File "/usr/local/envs/marl/lib/python3.6/multiprocessing/process.py", line 249, in _bootstrap
    self.run()
  File "/usr/local/envs/marl/lib/python3.6/multiprocessing/process.py", line 93, in run
    self._target(*self._args, **self._kwargs)
  File "/content/drive/MyDrive/on-policy/onpolicy/envs/env_wrappers.py", line 316, in shareworker
    ob, s_ob, available_actions = env.reset()
  File "/content/drive/MyDrive/on-policy/onpolicy/envs/starcraft2/StarCraft2_Env.py", line 388, in reset
    self._launch()
  File "/content/drive/MyDrive/on-policy/onpolicy/envs/starcraft2/StarCraft2_Env.py", line 338, in _launch
    self._sc2_proc = self._run_config.start(window_size=self.window_size, want_rgb=False)
  File "/usr/local/envs/marl/lib/python3.6/site-packages/pysc2/run_configs/platforms.py", line 205, in start
    want_rgb=want_rgb, extra_args=extra_args, **kwargs)
  File "/usr/local/envs/marl/lib/python3.6/site-packages/pysc2/run_configs/platforms.py", line 88, in start
    self, exec_path=exec_path, version=self.version, **kwargs)
  File "/usr/local/envs/marl/lib/python3.6/site-packages/pysc2/lib/sc_process.py", line 140, in __init__
    self._proc = self._launch(run_config, args, **kwargs)
  File "/usr/local/envs/marl/lib/python3.6/site-packages/pysc2/lib/sc_process.py", line 204, in _launch
    raise SC2LaunchError("Failed to launch: %s" % args)
pysc2.lib.sc_process.SC2LaunchError: Failed to launch: ['/content/drive/MyDrive/on-policy/StarCraftII/Versions/Base75689/SC2_x64', '-listen', '127.0.0.1', '-port', '20833', '-dataDir', '/content/drive/MyDrive/on-policy/StarCraftII/', '-tempDir', '/tmp/sc-xgv70coa/']
Traceback (most recent call last):
  File "/usr/local/envs/marl/lib/python3.6/site-packages/pysc2/lib/sc_process.py", line 201, in _launch
    return subprocess.Popen(args, cwd=run_config.cwd, env=run_config.env)
  File "/usr/local/envs/marl/lib/python3.6/subprocess.py", line 707, in __init__
    restore_signals, start_new_session)
  File "/usr/local/envs/marl/lib/python3.6/subprocess.py", line 1326, in _execute_child
    raise child_exception_type(errno_num, err_msg)
PermissionError: [Errno 13] Permission denied

During handling of the above exception, another exception occurred:

Traceback (most recent call last):
  File "/usr/local/envs/marl/lib/python3.6/multiprocessing/process.py", line 249, in _bootstrap
    self.run()
  File "/usr/local/envs/marl/lib/python3.6/multiprocessing/process.py", line 93, in run
    self._target(*self._args, **self._kwargs)
  File "/content/drive/MyDrive/on-policy/onpolicy/envs/env_wrappers.py", line 316, in shareworker
    ob, s_ob, available_actions = env.reset()
  File "/content/drive/MyDrive/on-policy/onpolicy/envs/starcraft2/StarCraft2_Env.py", line 388, in reset
    self._launch()
  File "/content/drive/MyDrive/on-policy/onpolicy/envs/starcraft2/StarCraft2_Env.py", line 338, in _launch
    self._sc2_proc = self._run_config.start(window_size=self.window_size, want_rgb=False)
  File "/usr/local/envs/marl/lib/python3.6/site-packages/pysc2/run_configs/platforms.py", line 205, in start
    want_rgb=want_rgb, extra_args=extra_args, **kwargs)
  File "/usr/local/envs/marl/lib/python3.6/site-packages/pysc2/run_configs/platforms.py", line 88, in start
    self, exec_path=exec_path, version=self.version, **kwargs)
  File "/usr/local/envs/marl/lib/python3.6/site-packages/pysc2/lib/sc_process.py", line 140, in __init__
    self._proc = self._launch(run_config, args, **kwargs)
  File "/usr/local/envs/marl/lib/python3.6/site-packages/pysc2/lib/sc_process.py", line 204, in _launch
    raise SC2LaunchError("Failed to launch: %s" % args)
pysc2.lib.sc_process.SC2LaunchError: Failed to launch: ['/content/drive/MyDrive/on-policy/StarCraftII/Versions/Base75689/SC2_x64', '-listen', '127.0.0.1', '-port', '15366', '-dataDir', '/content/drive/MyDrive/on-policy/StarCraftII/', '-tempDir', '/tmp/sc-_st0uxd0/']
Traceback (most recent call last):
  File "/usr/local/envs/marl/lib/python3.6/site-packages/pysc2/lib/sc_process.py", line 201, in _launch
    return subprocess.Popen(args, cwd=run_config.cwd, env=run_config.env)
  File "/usr/local/envs/marl/lib/python3.6/subprocess.py", line 707, in __init__
    restore_signals, start_new_session)
  File "/usr/local/envs/marl/lib/python3.6/subprocess.py", line 1326, in _execute_child
    raise child_exception_type(errno_num, err_msg)
PermissionError: [Errno 13] Permission denied

During handling of the above exception, another exception occurred:

Traceback (most recent call last):
  File "/usr/local/envs/marl/lib/python3.6/multiprocessing/process.py", line 249, in _bootstrap
    self.run()
  File "/usr/local/envs/marl/lib/python3.6/multiprocessing/process.py", line 93, in run
    self._target(*self._args, **self._kwargs)
  File "/content/drive/MyDrive/on-policy/onpolicy/envs/env_wrappers.py", line 316, in shareworker
    ob, s_ob, available_actions = env.reset()
  File "/content/drive/MyDrive/on-policy/onpolicy/envs/starcraft2/StarCraft2_Env.py", line 388, in reset
    self._launch()
  File "/content/drive/MyDrive/on-policy/onpolicy/envs/starcraft2/StarCraft2_Env.py", line 338, in _launch
    self._sc2_proc = self._run_config.start(window_size=self.window_size, want_rgb=False)
  File "/usr/local/envs/marl/lib/python3.6/site-packages/pysc2/run_configs/platforms.py", line 205, in start
    want_rgb=want_rgb, extra_args=extra_args, **kwargs)
  File "/usr/local/envs/marl/lib/python3.6/site-packages/pysc2/run_configs/platforms.py", line 88, in start
    self, exec_path=exec_path, version=self.version, **kwargs)
  File "/usr/local/envs/marl/lib/python3.6/site-packages/pysc2/lib/sc_process.py", line 140, in __init__
    self._proc = self._launch(run_config, args, **kwargs)
  File "/usr/local/envs/marl/lib/python3.6/site-packages/pysc2/lib/sc_process.py", line 204, in _launch
    raise SC2LaunchError("Failed to launch: %s" % args)
pysc2.lib.sc_process.SC2LaunchError: Failed to launch: ['/content/drive/MyDrive/on-policy/StarCraftII/Versions/Base75689/SC2_x64', '-listen', '127.0.0.1', '-port', '24420', '-dataDir', '/content/drive/MyDrive/on-policy/StarCraftII/', '-tempDir', '/tmp/sc-xoifnzwl/']
Traceback (most recent call last):
  File "/usr/local/envs/marl/lib/python3.6/site-packages/pysc2/lib/sc_process.py", line 201, in _launch
    return subprocess.Popen(args, cwd=run_config.cwd, env=run_config.env)
  File "/usr/local/envs/marl/lib/python3.6/subprocess.py", line 707, in __init__
    restore_signals, start_new_session)
  File "/usr/local/envs/marl/lib/python3.6/subprocess.py", line 1326, in _execute_child
    raise child_exception_type(errno_num, err_msg)
PermissionError: [Errno 13] Permission denied

During handling of the above exception, another exception occurred:

Traceback (most recent call last):
  File "/usr/local/envs/marl/lib/python3.6/multiprocessing/process.py", line 249, in _bootstrap
    self.run()
  File "/usr/local/envs/marl/lib/python3.6/multiprocessing/process.py", line 93, in run
    self._target(*self._args, **self._kwargs)
  File "/content/drive/MyDrive/on-policy/onpolicy/envs/env_wrappers.py", line 316, in shareworker
    ob, s_ob, available_actions = env.reset()
  File "/content/drive/MyDrive/on-policy/onpolicy/envs/starcraft2/StarCraft2_Env.py", line 388, in reset
    self._launch()
  File "/content/drive/MyDrive/on-policy/onpolicy/envs/starcraft2/StarCraft2_Env.py", line 338, in _launch
    self._sc2_proc = self._run_config.start(window_size=self.window_size, want_rgb=False)
  File "/usr/local/envs/marl/lib/python3.6/site-packages/pysc2/run_configs/platforms.py", line 205, in start
    want_rgb=want_rgb, extra_args=extra_args, **kwargs)
  File "/usr/local/envs/marl/lib/python3.6/site-packages/pysc2/run_configs/platforms.py", line 88, in start
    self, exec_path=exec_path, version=self.version, **kwargs)
  File "/usr/local/envs/marl/lib/python3.6/site-packages/pysc2/lib/sc_process.py", line 140, in __init__
    self._proc = self._launch(run_config, args, **kwargs)
  File "/usr/local/envs/marl/lib/python3.6/site-packages/pysc2/lib/sc_process.py", line 204, in _launch
    raise SC2LaunchError("Failed to launch: %s" % args)
pysc2.lib.sc_process.SC2LaunchError: Failed to launch: ['/content/drive/MyDrive/on-policy/StarCraftII/Versions/Base75689/SC2_x64', '-listen', '127.0.0.1', '-port', '20477', '-dataDir', '/content/drive/MyDrive/on-policy/StarCraftII/', '-tempDir', '/tmp/sc-y9tciajk/']
Traceback (most recent call last):
  File "/usr/local/envs/marl/lib/python3.6/site-packages/pysc2/lib/sc_process.py", line 201, in _launch
    return subprocess.Popen(args, cwd=run_config.cwd, env=run_config.env)
  File "/usr/local/envs/marl/lib/python3.6/subprocess.py", line 707, in __init__
    restore_signals, start_new_session)
  File "/usr/local/envs/marl/lib/python3.6/subprocess.py", line 1326, in _execute_child
    raise child_exception_type(errno_num, err_msg)
PermissionError: [Errno 13] Permission denied

During handling of the above exception, another exception occurred:

Traceback (most recent call last):
  File "/usr/local/envs/marl/lib/python3.6/multiprocessing/process.py", line 249, in _bootstrap
    self.run()
  File "/usr/local/envs/marl/lib/python3.6/multiprocessing/process.py", line 93, in run
    self._target(*self._args, **self._kwargs)
  File "/content/drive/MyDrive/on-policy/onpolicy/envs/env_wrappers.py", line 316, in shareworker
    ob, s_ob, available_actions = env.reset()
  File "/content/drive/MyDrive/on-policy/onpolicy/envs/starcraft2/StarCraft2_Env.py", line 388, in reset
    self._launch()
  File "/content/drive/MyDrive/on-policy/onpolicy/envs/starcraft2/StarCraft2_Env.py", line 338, in _launch
    self._sc2_proc = self._run_config.start(window_size=self.window_size, want_rgb=False)
  File "/usr/local/envs/marl/lib/python3.6/site-packages/pysc2/run_configs/platforms.py", line 205, in start
    want_rgb=want_rgb, extra_args=extra_args, **kwargs)
  File "/usr/local/envs/marl/lib/python3.6/site-packages/pysc2/run_configs/platforms.py", line 88, in start
    self, exec_path=exec_path, version=self.version, **kwargs)
  File "/usr/local/envs/marl/lib/python3.6/site-packages/pysc2/lib/sc_process.py", line 140, in __init__
    self._proc = self._launch(run_config, args, **kwargs)
  F